Traceback (most recent call last):
  File "/opt/hostedtoolcache/Python/3.7.9/x64/lib/python3.7/site-packages/jupyter_cache/executors/utils.py", line 56, in single_nb_execution
    record_timing=False,
  File "/opt/hostedtoolcache/Python/3.7.9/x64/lib/python3.7/site-packages/nbclient/client.py", line 1087, in execute
    return NotebookClient(nb=nb, resources=resources, km=km, **kwargs).execute()
  File "/opt/hostedtoolcache/Python/3.7.9/x64/lib/python3.7/site-packages/nbclient/util.py", line 74, in wrapped
    return just_run(coro(*args, **kwargs))
  File "/opt/hostedtoolcache/Python/3.7.9/x64/lib/python3.7/site-packages/nbclient/util.py", line 53, in just_run
    return loop.run_until_complete(coro)
  File "/opt/hostedtoolcache/Python/3.7.9/x64/lib/python3.7/asyncio/base_events.py", line 587, in run_until_complete
    return future.result()
  File "/opt/hostedtoolcache/Python/3.7.9/x64/lib/python3.7/site-packages/nbclient/client.py", line 541, in async_execute
    cell, index, execution_count=self.code_cells_executed + 1
  File "/opt/hostedtoolcache/Python/3.7.9/x64/lib/python3.7/site-packages/nbclient/client.py", line 832, in async_execute_cell
    self._check_raise_for_error(cell, exec_reply)
  File "/opt/hostedtoolcache/Python/3.7.9/x64/lib/python3.7/site-packages/nbclient/client.py", line 740, in _check_raise_for_error
    raise CellExecutionError.from_cell_and_msg(cell, exec_reply['content'])
nbclient.exceptions.CellExecutionError: An error occurred while executing the following cell:
------------------
# Plot the function, the prediction and the 95% confidence interval based on
# the MSE
plt.figure(figsize=(19,8))
plt.plot(x_test.ravel(), y.ravel(), 'r:', label=r'$f(x) = x\,\sin(x)$')
plt.plot(x_train, y_train, 'r.', markersize=10, label='Observations')
plt.plot(x_test, y_pred, 'b-', label='Prediction')
plt.fill(np.concatenate([x_test, x_test[::-1]]),
         np.concatenate([y_pred - 1.9600 * sigma,
                        (y_pred + 1.9600 * sigma)[::-1]]),
         alpha=.5, fc='b', ec='None', label='95% confidence interval')
plt.xlabel('$x$')
plt.ylabel('$f(x)$')
plt.ylim(-3, 3)
plt.legend(loc='upper left')
------------------

[0;31m---------------------------------------------------------------------------[0m
[0;31mNameError[0m                                 Traceback (most recent call last)
[0;32m<ipython-input-18-6a94b2975418>[0m in [0;36m<module>[0;34m[0m
[1;32m      1[0m [0;31m# Plot the function, the prediction and the 95% confidence interval based on[0m[0;34m[0m[0;34m[0m[0;34m[0m[0m
[1;32m      2[0m [0;31m# the MSE[0m[0;34m[0m[0;34m[0m[0;34m[0m[0m
[0;32m----> 3[0;31m [0mplt[0m[0;34m.[0m[0mfigure[0m[0;34m([0m[0mfigsize[0m[0;34m=[0m[0;34m([0m[0;36m19[0m[0;34m,[0m[0;36m8[0m[0;34m)[0m[0;34m)[0m[0;34m[0m[0;34m[0m[0m
[0m[1;32m      4[0m [0mplt[0m[0;34m.[0m[0mplot[0m[0;34m([0m[0mx_test[0m[0;34m.[0m[0mravel[0m[0;34m([0m[0;34m)[0m[0;34m,[0m [0my[0m[0;34m.[0m[0mravel[0m[0;34m([0m[0;34m)[0m[0;34m,[0m [0;34m'r:'[0m[0;34m,[0m [0mlabel[0m[0;34m=[0m[0;34mr'$f(x) = x\,\sin(x)$'[0m[0;34m)[0m[0;34m[0m[0;34m[0m[0m
[1;32m      5[0m [0mplt[0m[0;34m.[0m[0mplot[0m[0;34m([0m[0mx_train[0m[0;34m,[0m [0my_train[0m[0;34m,[0m [0;34m'r.'[0m[0;34m,[0m [0mmarkersize[0m[0;34m=[0m[0;36m10[0m[0;34m,[0m [0mlabel[0m[0;34m=[0m[0;34m'Observations'[0m[0;34m)[0m[0;34m[0m[0;34m[0m[0m

[0;31mNameError[0m: name 'plt' is not defined
NameError: name 'plt' is not defined

